Workbook

Sheet Instruções
C2: Intruções de Preenchimento
B5: Objetivo deste documento: | C5: Armazenar todo documento de Gerenciamento do Projeto, utilizado pela coordenação deste, bem como todas as solicitações de mudanças nos projetos; Controle de Versões; Pendências; Recursos e Riscos.
B7: Documento | C7: Obrigatoriedade | D7: Descrição
B8: Declaração de Escopo do Projeto | C8: X | D8: Fornece o entendimento comum do Projeto a todas as partes interessadas, descrevendo os principais objetivos, escopo, processos da Cadeia de Valor tratados, produtos ou serviços, premissas, restrições, entregáveis e matriz hierárquica.
B9: Classificação do processo | C9: X | D9: Classificação do Gestor do processo quanto ao nível de segurança das informações que serão modeladas, onde: Confidencial: deve ser atribuída às informações que garantem à conpanhia a obtenção de vantagens competitivas; às que descrevem uma parte significante dos seus negócios; às que contêm estratégias operacionais de longo prazo; e àquelas que têm um impacto potencialmente sério nas políticas e práticas relacionadas a recursos humanos. Corporativo: deve ser atribuída às informações que podem ser de conhecimento dos usuários internos da companhia; Reservado: deve ser atribuída às informações que garantem à companhia a manutenção das suas vantagens competitivas; às que descrevem uma parte dos seus negócios; às que contêm planos operacionais de curto e médio prazo.
B10: WBS ou EAP | C10: X | D10: Descreve o objetivo, métrica e o tipo de trabalho que será realizado ou a entrega. É responsável por garantir o entendimento do produto ou a entrega que serão gerados pela equipe do projeto. A estrutura desenhada deverá ser apresentada à parte em Microsoft Word ou Excel ou Power Point ou ainda em formato de figura.
B11: Orçamento | C11: X | D11: Previsão de custos despendidos com os recursos necessários para execução do projeto(neste modelo, restrito à custos de aquisições + consultoria);
B12: Cronograma inicial | C12: X | D12: Cronograma inicial para aprovação do projeto. Contém as etapas do projeto nível macro, com os marcos, data de inicício e previsão de término. OBS: O Cronograma completo deverá ser apresentado à parte, com todos os eventos do projeto.
B13: Stakeholders | C13: X | D13: Define os membros que serão stakeholders e suas especifidades de função no projeto e identifica a existência de grupos de stakeholders externos à organização.
B14: Recursos | C14: X | D14: Relaciona as informações dos recursos humanos envolvidos para execução do projeto e seus horários de participação.
B15: Matriz de Responsabilidades | C15: X | D15: Define as responsabilidades e sua abrangência para todos os envolvidos no projeto.
B16: Plano de Comunicação | C16: X | D16: Define todas as reuniões e eventos previstos no projeto e suas especifidades.
B17: Plano de Riscos | C17: X | D17: Estabelece um plano de ação para tratar os riscos de acordo com a identificação e/ou análise. Todo e qualquer risco identificado, tornará o preenchimento deste documento obrigatório.
B18: Solicitação de Mudanças | D18: Documento utilizado para registrar, avaliar e controlar as solicitações de alterações no projeto. Toda e qualquer mudança no projeto, tornará o preenchimento deste documento obrigatório.
B19: Termo de Encerramento | C19: X | D19: Fornece as informações sobre o término do projeto e suas entregas incluindo a sua avaliação e a aprovação do encerramento.
B20: Versões | D20: Utilizado para acompanhar e registrar as alterações realizadas nas diversas planilhas deste documento incluindo os documentos WBS e cronograma.
B22: Aprovações
B24: Data: 23/10/2026 | C24: Gerente do projeto: Fernanda

Sheet TAP
A1: Termo de Abertura do projeto
A3: Controle de versões
A4: Versão | C4: Data | E4: Autor | G4: Notas de revisão
A5: 1 | C5: 46318 | E5: Matheus e Marciane | G5: revisado
A6: 2
A8: 1. IDENTIFICAÇÃO
A10: Nome do Projeto: | C10: Vertex Londrina 360
A12: Objetivo do documento: | C12: Autorizar o início do projeto, atribuir principais responsáveis e documentar requisitos iniciais, principais entregas, premissas e restrições.
A14: Projeto: | C14: Conforme previsto no plano estratégico
A16: 2. JUSTIFICATIVA
A17: O empreendimento Vertex Londrina 360 justifica-se pela oportunidade de criar uma edificação icônica, sustentável e multifuncional, capaz de integrar, em um único projeto, espaços destinados a atividades comerciais, residenciais e turísticas. Essa combinação amplia a atratividade do empreendimento e fortalece sua proposta de valor ao atender diferentes públicos e finalidades de uso. A adoção de uma fachada em cimento geopolimérico fotocatalítico com dióxido de titânio (TiO₂) reforça o compromisso do projeto com inovação, sustentabilidade e redução de impactos ambientais. A tecnologia foi incorporada à proposta para viabilizar propriedades de autolimpeza e despoluição ambiental, em alinhamento com critérios ESG e de ciclo de vida previstos no projeto. Além de seu valor arquitetônico, o empreendimento representa um desafio estratégico de engenharia e gestão: construir uma torre autoportante, em escala 1:350, integralmente inserida em uma área máxima de 1 m², mantendo estabilidade estrutural, fidelidade ao croqui homologado, qualidade estética e eficiência na utilização dos materiais. Sob a perspectiva gerencial, o projeto também permite demonstrar a capacidade da Vertex Engenharia Brasil de integrar planejamento, engenharia, suprimentos, gestão de riscos, controle orçamentário, auditoria e documentação. A execução deverá respeitar o limite de US$ 20.000.000,00, as regras de aquisição e concorrência e o prazo estabelecido para a entrega física e documental. Dessa forma, o Vertex Londrina 360 posiciona-se como uma referência de inovação construtiva, sustentabilidade e excelência em gestão de projetos, transformando uma solução arquitetônica de grande impacto em uma entrega tecnicamente consistente, financeiramente controlada e alinhada às expectativas do cliente.
A18: 3. OBJETIVO
A19: Projetar, viabilizar e construir a maior torre em Londrina como um marco arquitetônico e visual da cidade, uma torre corporativa e multifuncional, posicionada entre as edificações mais altas do mundo. O empreendimento integra com equilíbrio arquitetônico uma tripla vocação comercial, residencial e turístico. O projeto busca integrar beleza, inovação, segurança, eficiência e sustentabilidade, adotando soluções construtivas diferenciadas e princípios de logística reversa, de forma a contribuir para o desenvolvimento urbano, além de posicionar a Vertex Engenharia Brasil como referência em engenharia inovadora e sustentável.adotando tecnologia ativa de cimento geopolimérico fotocatalítico com TiO2 para autolimpeza e despoluição ambiental em conformidade com critérios ESG e de ciclo de vida (EN 15804).
A21: 4. ESCOPO
A22: 4.1. Descrição | B22: 4.1. Descrição
A23: O projeto compreende o planejamento, a construção e a entrega da LendLease Aurora Tower, uma torre corporativa e multifuncional. A torre será composta por três segmentos funcionais: comercial, residencial e turístico, incorporando fachada integralmente fechada em cimento geopolimérico fotocatalítico com dióxido de titânio. A construção deverá manter fidelidade ao croqui homologado, estabilidade estrutural, simetria e acabamento compatível com os critérios de avaliação. O escopo gerencial contempla a elaboração e a consolidação dos 15 artefatos do template oficial, o controle do orçamento dentro do limite de US$ 20.000.000,00, a gestão dos riscos, a auditoria cruzada do concorrente, o controle das aquisições e a entrega do edifício protótipo, com no mínimo 2 metros até as 16:30 do dia 23/10/2026, construído com os materiais adquirido com o fornecedor Bueno.
A24: 4.2. Marcos | B24: 4.3. Objetivos específicos
A25: 4.2.1: Projeto autorizado: TAP aprovado e governança estabelecida. 4.2.2: Solução homologada: croqui, requisitos e critérios técnicos validados. 4.2.3: Recursos assegurados: materiais adquiridos e orçamento protegido. 4.2.4: Estrutura estabilizada: torre autoportante construída dentro da área delimitada construída a partir dos materiais fornecidos até as 16h30 de 23/10/2026. 4.2.5: Gestão consolidada: 15 artefatos gerenciais finalizados e revisados. 4.2.6: Conformidade demonstrada: auditoria cruzada realizada e documentação enviada ao Stakeholder Ricardo.
A26: 5. PRAZO ESTIMADO
A27: 7h e 30min
A28: 6. ORÇAMENTO ESTIMADO
A29: Diponibilidade orçamentária U$ 20.000.000,00
A30: 7. PRINCIPAIS PARTES INTERESSADAS
A32: 8. EQUIPE DE PROJETO
A33: Fernanda Carlos Eduardo Everton Fabi João Diego Matheus Marciane
A34: 9. PRINCIPAIS RISCOS, FATORES CRÍTICOS, PREMISSAS OU RESTRIÇÕES
A35: 9.1. Principais riscos | B35: 4.1. Descrição
A36: Riscos do Projeto Colapso ou tombamento estrutural da torre: Risco de instabilidade física vertical por vento, falha de contraventamento ou sobrecarga nas emendas, levando à reprovação sumária da entrega perante a banca. Monopólio do fornecedor Bueno e desabastecimento de cimento geopolimérico: Vulnerabilidade à fixação de preços e atrasos na entrega dos kits fechados pelo fornecedor exclusivo, paralisando a montagem da fachada. Autuação e aplicação de multa por infração concorrencial: Risco de sanção no valor de US$ 1.000.000,00 caso ocorra qualquer transação monetária ou compra compartilhada com empresas concorrentes. Estouro de orçamento por alterações não planejadas: Custo mandatório de US$ 100.000,00 para cada solicitação de mudança pós-apresentação formal do plano, gerando corrosão das reservas financeiras. Discrepância geométrica entre croqui e obra física: Penalização ou perda de pontos no critério de simetria e estética caso a torre executada apresente desvios visuais em relação ao desenho técnico homologado. Perda ou rasgo de placas cimentícias (folhas A4): Impossibilidade de fechar 100% da fachada devido a danos mecânicos durante a dobragem/colagem, sem possibilidade de devolução ou recompra de kits fracionados. Extrapolação do horário de entrega (prazo fatal): Atraso na finalização da obra física ou na submissão do dossiê documental único até às 16:30, resultando em pontuação mínima de prazo ou desclassificação.
A37: 9.2. Fatores críticos de sucesso | B37: 4.1. Descrição
A38: Estabilidade e autossustentação da estrutura: A torre deve permanecer íntegra e autoportante apoiada no piso até o encerramento da avaliação final. Fechamento e vedação completa da fachada: Aplicação contínua das placas cimentícias geopoliméricas (folhas A4) em todo o perímetro do edifício. Aderência rigorosa à escala e simetria: Fidelidade dimensional à proporção 1:350, mantendo proporcionalidade volumétrica e alinhamento visual com o croqui arquitetônico. Pontualidade na entrega integrada: Conclusão da montagem física da torre e envio do arquivo consolidado de documentação antes das 16:30 para o facilitador. Equilíbrio orçamentário e conformidade fiscal: Execução de todas as aquisições dentro do teto de US$ 20.000.000,00, buscando mitigar ocorrências de multas regulatórias. Aprovação na auditoria cruzada: Rastreabilidade e consistência documental entre o planejado e o realizado, suportando a auditoria externa do concorrente.
A39: 9.3. Premissas | B39: 4.1. Descrição
A40: Disponibilidade contínua de insumos pelo fornecedor: Assume-se que o fornecedor Bueno manterá estoque suficiente de kits fechados para atendimento imediato no horário de aquisições (14:20 às 14:30). Apoio e cooperação interorganizacional sem moeda: Premissa de que as empresas concorrentes estarão dispostas a realizar permutas e doações físicas de insumos excedentes para otimização mútua. Integridade dos insumos fornecidos: Assume-se que as folhas de papel A4, fitas adesivas e todos os materiais recebidos atendem aos requisitos de resistência mecânica e propriedades de manuseio esperados. Conectividade e estabilidade dos canais digitais: Premissa de funcionamento do e-mail corporativo para o envio tempestivo do dossiê em arquivo único até o limite das 16:30. Autonomia da gestão de projeto: A liderança possui autoridade para alocar papéis internos e ajustar métodos operacionais de acordo com a estratégia corporativa aprovada.
A41: 9.4. Restrições | B41: 4.1. Descrição
A42: Restrição Orçamentária: Teto financeiro improrrogável de US$ 20.000.000,00 para aquisição de materiais e cobertura de contingências. Restrição Temporal e Marcos da Agenda: Cumprimento estrito dos marcos horários, com conclusão física/documental mandatória até às 16:30. Restrição Espacial e Territorial: A obra deve ser obrigatoriamente construída dentro do terreno delimitado por fita adesiva no piso, na área designada próxima à mesa da equipe. Restrição Física de Altura: A torre tem como limite superior intransponível o teto físico da sala de aula. Restrições de Compras e Fornecimento: Proibição de compras fracionadas (apenas kits fechados), proibição de devolução de sobras e proibição de transações monetárias entre equipes concorrentes. Restrição de Governança Documental: Obrigatoriedade de submissão do dossiê em arquivo único estruturado a partir do template oficial homologado pelo cliente.
A43: 10. RESPONSÁVEIS
A45: Patrocinador: | C45: Nick O´Neil
A46: Telefone:
A47: E-mail:
A49: Gerente: | C49: Fernanda Leandro Fonseca de Souza
A50: Telefone: | C50: (61) 98110-0155
...

Sheet EAP

Sheet Declaração de Escopo do Projeto
F3: Declaração de escopo do Projeto
B5: 1. Nome do Projeto
B7: Vertex Londrina 360 | K7: Cliente
B9: Data: | C9: 46318 | E9: Sigla do projeto: | G9: VL | J9: x | K9: Corporativo
B11: Classificação do processo: | E11: CORPORATIVO
B13: 2. Objetivo / Escopo
B15: Projetar, viabilizar e construir uma torre corporativa e multifuncional de grande porte na escala física de 1:350, posicionada entre as edificações mais altas do mundo sem contato com o teto físico do ambiente, implantada estritamente dentro da área limite de 1 m² demarcada no piso. O empreendimento integra com equilíbrio arquitetônico uma tripla vocação (1/3 comercial, 1/3 residencial e 1/3 turístico), adotando tecnologia ativa de cimento geopolimérico fotocatalítico com TiO2 para autolimpeza e despoluição ambiental em conformidade com critérios ESG e de ciclo de vida (EN 15804), mantendo o custo contido no teto orçamentário de US$ 20.000.000,00 e concluindo todas as entregas gerenciais e físicas até às 16:30 do dia 23/10/2026.
B22: 3. Processo(s) da Cadeia de Valor de EAP
B24: Declaração de escopo;
B25: Elaboração de cronograma;
B26: Elaboração dos planos de qualidade, custos, stakeholders, aquisições, risco, comunicação, recursos humanos;
B27: Aquisição dos materiais;
B28: Execução da estrutura;
B29: Elaboração da matriz de responsabilidades;
B30: Termo de encerramento com lições aprendidas.
B33: 4. Justificativa
B35: O empreendimento Vertex Aurora 360 justifica-se pela oportunidade de criar uma edificação icônica, sustentável e multifuncional, capaz de integrar, em um único projeto, espaços destinados a atividades comerciais, residenciais e turísticas. Essa combinação amplia a atratividade do empreendimento e fortalece sua proposta de valor ao atender diferentes públicos e finalidades de uso. A adoção de uma fachada em cimento geopolimérico fotocatalítico com dióxido de titânio (TiO₂) reforça o compromisso do projeto com inovação, sustentabilidade e redução de impactos ambientais. A tecnologia foi incorporada à proposta para viabilizar propriedades de autolimpeza e despoluição ambiental, em alinhamento com critérios ESG e de ciclo de vida previstos no projeto. Além de seu valor arquitetônico, o empreendimento representa um desafio estratégico de engenharia e gestão: construir uma torre autoportante, em escala 1:350, integralmente inserida em uma área máxima de 1 m², mantendo estabilidade estrutural, fidelidade ao croqui homologado, qualidade estética e eficiência na utilização dos materiais. Sob a perspectiva gerencial, o projeto também permite demonstrar a capacidade da Vertex Engenharia Brasil de integrar planejamento, engenharia, suprimentos, gestão de riscos, controle orçamentário, auditoria e documentação. A execução deverá respeitar o limite de US$ 20.000.000,00, as regras de aquisição e concorrência e o prazo estabelecido para a entrega física e documental. Dessa forma, o Vertex Aurora 360 posiciona-se como uma referência de inovação construtiva, sustentabilidade e excelência em gestão de projetos, transformando uma solução arquitetônica de grande impacto em uma entrega tecnicamente consistente, financeiramente controlada e alinhada às expectativas do cliente. Ajustes realizados: a justificativa conecta a necessidade do empreendimento aos seus diferenciais comerciais, ambientais, técnicos e gerenciais, evitando repetir apenas o objetivo ou a descrição do escopo.
... B82: 9. Matriz Hierárquica

Sheet Cronograma Inicial
E2: Cronograma
B3: ='Declaração de Escopo do Projeto'!B7:H7 -> Vertex Londrina 360
B5: Marco do Projeto | C5: Responsável | D5: Duração | E5: Data de Entrega
B8: Escopo estratégico aprovado | C8: Gerente do Projeto | D8: Marco | E8: 23/10 – 11:00
B9: Entregas e materiais aprovados | C9: Gerente do Projeto | D9: Marco | E9: 23/10 – 11:30
B10: Croqui estrutural aprovado | C10: Engenharia | D10: Marco | E10: 23/10 – 12:00
B11: Plano de aquisições aprovado | C11: Suprimentos | D11: Marco | E11: 23/10 – 12:30
B12: Área de implantação liberada | C12: Sponsor | D12: Marco | E12: 23/10 – 14:30
B13: Materiais adquiridos | C13: Suprimentos | D13: Marco | E13: 23/10 – 14:40
B14: Torre concluída e documentação entregue | C14: Engenharia / Gerente do Projeto | D14: Marco | E14: 23/10 – 16:30
B15: Projeto avaliado e encerrado | C15: Gerente do Projeto / Sponsor | D15: Marco | E15: 23/10 – 18:00
B26: Obs. essa planilha mostra os principais gates do projeto

Sheet Recursos
C2: Recursos
B3: ='Declaração de Escopo do Projeto'!B7:H7 -> Vertex Londrina 360
B5: Horário dos Recursos
B6: Turno | C6: Segunda | D6: Terça | E6: Quarta | F6: Quinta | G6: Sexta
B7: Manhã | C7: 0.375 | D7: 0.375 | E7: 0.375 | F7: 0.375 | G7: 0.375
B8: Tarde | C8: 0.75 | D8: 0.75 | E8: 0.75 | F8: 0.75 | G8: 0.75
B10: Descrição dos Recursos
B11: Nome | C11: Chave ou E-mail | D11: Departamento | E11: Telefone Comercial | F11: Telefone Celular
B12: Fernanda | C12: fernanda.alves@example.com | D12: Gerente de Projeto | E12: (61) 3100-1201 | F12: (61) 99101-2201
B13: Diego | C13: diego.martins@example.com | D13: Bench | E13: (61) 3100-1202 | F13: (61) 99102-2202
B14: Carlos Eduardo | C14: carlos.eduardo@example.com | D14: Auditor | E14: (61) 3100-1203 | F14: (61) 99103-2203
B15: Matheus | C15: matheus.pessoa@example.com | D15: Documentação | E15: (61) 3100-1204 | F15: (61) 99104-2204
B16: Marciane | C16: marciane.silva@example.com | D16: Documentação | E16: (61) 3100-1205 | F16: (61) 99105-2205
B17: Everton | C17: everton.rocha@example.com | D17: Design e Engenharia | E17: (61) 3100-1206 | F17: (61) 99106-2206
B18: Fabi | C18: fabi.souza@example.com | D18: Design e Engenharia | E18: (61) 3100-1207 | F18: (61) 99107-2207
B19: João | C19: joao.lima@example.com | D19: Design e Engenharia | E19: (61) 3100-1208 | F19: (61) 99108-2208

Sheet Matriz de Responsabilidades
E2: Matriz de Responsabilidades
B3: ='Declaração de Escopo do Projeto'!B7:H7 -> Vertex Londrina 360
B5: Equipe de projeto | C5: Nome | D5: Responsabilidades
E6: Iniciação | G6: Planejamento | Y6: Execução | AD6: Controle | AL6: Encerramento
E7: Inic. | G7: Escopo | J7: Tempo | O7: Custos | Q7: Qualidade | R7: RH | S7: Aquisições | T7: Comunicações | U7: Riscos | X7: STKH | Y7: RH | AB7: Custos | AC7: Com. | AD7: Escopo | AF7: Tempo | AG7: Custos | AH7: Qual. | AI7: Custos | AJ7: Com. | AK7: Riscos | AL7: Custos | AM7: Integração
D8: Papéis Chaves | E8: Identificar partes interessadas | F8: Desenvolver p TAP | G8: Coletar requisitos | H8: Definir o escopo | I8: Criar a EAP | J8: Definir as atividades | K8: Sequenciar atividades | L8: Estimar os recursos das atividades | M8: Estimar as durações das atividades | N8: Desenvolver o cronograma | O8: Estimar custos | P8: Determinar o orçamento | Q8: Planejar o gerenciamento da qualidade | R8: Planejar o gerenciamento dos recursos humanos | S8: Planejar o gerenciamento das aquisições | T8: Planejar o gerenciamento das comunicações | U8: Identificar os riscos | V8: Realizar a análise qualitativa dos riscos | W8: Planejar as respostas aos riscos | X8: Planejar o gerenciamento das partes interessadas | Y8: Realizar a garantia de qualidade | Z8: Mobilizar a e desenvolver a equipe do projeto | AA8: Gerenciar a equipe do projeto | AB8: Conduzir as aquisições | AC8: Gerenciar as comunicações | AD8: Validar o escopo | AE8: Controlar o escopo | AF8: Controlar o cronograma | AG8: Controlar os custos | AH8: Controlar a qualidade | AI8: Controlar as aquisições | AJ8: Controlar as comunicações | AK8: Controlar os riscos | AL8: Encerrar as aquisições | AM8: Encerrar o projeto ou fase do projeto
C15: Fernanda | D15: Gerente de Projeto | E15: A | F15: R | G15: A | H15: R | I15: A | J15: R | K15: A | L15: A | M15: A | N15: A | O15: A | P15: A | Q15: A | R15: A | S15: A | T15: A | U15: A | V15: A | W15: A | X15: A | Y15: A | Z15: R | AA15: R | AB15: A | AC15: A | AD15: R | AE15: R | AF15: R | AG15: A | AH15: A | AI15: A | AJ15: A | AK15: R | AL15: A | AM15: R
C16: Nick O´Neil | D16: Sponsor | E16: I | F16: A | G16: C | H16: A | I16: I | J16: I | K16: I | L16: I | M16: I | N16: I | O16: I | P16: I | Q16: I | R16: I | S16: I | T16: I | U16: I | V16: I | W16: I | X16: I | Y16: I | Z16: I | AA16: I | AB16: I | AC16: I | AD16: A | AE16: A | AF16: I | AG16: I | AH16: I | AI16: I | AJ16: I | AK16: I | AL16: I | AM16: A
C17: Carlos Eduardo | D17: Auditor/Qualidade | E17: C | F17: Rv | G17: C | H17: Rv | I17: Rv | J17: Rv | K17: Rv | L17: Rv | M17: Rv | N17: Rv | O17: Rv | P17: Rv | Q17: Rv | R17: C | S17: Rv | T17: C | U17: C | V17: Rv | W17: Rv | X17: C | Y17: R | Z17: C | AA17: C | AB17: Rv | AC17: C | AD17: Rv | AE17: Rv | AF17: Rv | AG17: Rv | AH17: R | AI17: Rv | AJ17: C | AK17: Rv | AL17: Rv | AM17: Rv
C18: Bueno | D18: Fornecedor | E18: I | F18: I | G18: I | H18: I | I18: I | J18: I | K18: I | L18: C | M18: I | N18: I | O18: C | P18: I | Q18: I | R18: I | S18: C | T18: I | U18: C | V18: C | W18: C | X18: I | Y18: I | Z18: I | AA18: I | AB18: P | AC18: I | AD18: I | AE18: I | AF18: I | AG18: C | AH18: I | AI18: C | AJ18: I | AK18: C | AL18: P | AM18: I
C19: Prof. Ricardo Soares | D19: Facilitador | E19: R | F19: C | G19: R | H19: C | I19: C | J19: C | K19: C | L19: C | M19: C | N19: C | O19: C | P19: C | Q19: C | R19: Rv | S19: C | T19: C | U19: R | V19: C | W19: C | X19: R | Y19: C | Z19: P | AA19: C | AB19: C | AC19: C | AD19: C | AE19: C | AF19: C | AG19: C | AH19: C | AI19: C | AJ19: C | AK19: C | AL19: C | AM19: C
C20: Everton | D20: Design e Engenharia | E20: C | F20: C | G20: P | H20: C | I20: R | J20: C | K20: R | L20: C | M20: R | N20: C | O20: C | P20: C | Q20: R | R20: C | S20: C | T20: C | U20: P | V20: R | W20: R | X20: C | Y20: P | Z20: P | AA20: P | AB20: C | AC20: C | AD20: C | AE20: C | AF20: P | AG20: C | AH20: P | AI20: C | AJ20: C | AK20: P | AL20: I | AM20: C
C21: Fabi | D21: Design e Engenharia | E21: C | F21: C | G21: P | H21: C | I21: P | J21: C | K21: P | L21: C | M21: P | N21: C | O21: C | P21: C | Q21: P | R21: C | S21: C | T21: C | U21: P | V21: P | W21: P | X21: C | Y21: P | Z21: P | AA21: P | AB21: C | AC21: C | AD21: C | AE21: C | AF21: P | AG21: C | AH21: P | AI21: C | AJ21: C | AK21: P | AL21: I | AM21: C
C22: João | D22: Suprimentos e Logística | E22: C | F22: I | G22: C | H22: C | I22: C | J22: C | K22: C | L22: R | M22: C | N22: C | O22: R | P22: R | Q22: C | R22: C | S22: R | T22: C | U22: C | V22: C | W22: P | X22: C | Y22: C | Z22: C | AA22: C | AB22: R | AC22: C | AD22: C | AE22: C | AF22: C | AG22: R | AH22: C | AI22: R | AJ22: C | AK22: C | AL22: R | AM22: C
C23: Diego | D23: Bench | E23: C | F23: I | G23: P | H23: C | I23: P | J23: P | K23: P | L23: P | M23: P | N23: C | O23: I | P23: I | Q23: P | R23: P | S23: I | T23: C | U23: P | V23: P | W23: P | X23: P | Y23: P | Z23: P | AA23: P | AB23: P | AC23: P | AD23: C | AE23: C | AF23: P | AG23: I | AH23: P | AI23: I | AJ23: P | AK23: P | AL23: I | AM23: I
C24: Matheus | D24: Documentação | E24: Rv | F24: P | G24: Rv | H24: P | I24: P | J24: P | K24: C | L24: C | M24: C | N24: R | O24: C | P24: C | Q24: C | R24: R | S24: P | T24: R | U24: P | V24: P | W24: C | X24: P | Y24: Rv | Z24: I | AA24: I | AB24: I | AC24: R | AD24: P | AE24: P | AF24: C | AG24: C | AH24: C | AI24: C | AJ24: R | AK24: C | AL24: C | AM24: P
C25: Marciane | D25: Documentação | E25: P | F25: P | G25: P | H25: P | I25: P | J25: P | K25: C | L25: C | M25: C | N25: P | O25: C | P25: C | Q25: C | R25: P | S25: P | T25: Rv | U25: P | V25: P | W25: C | X25: P | Y25: P | Z25: I | AA25: I | AB25: I | AC25: Rv | AD25: P | AE25: P | AF25: C | AG25: C | AH25: C | AI25: C | AJ25: Rv | AK25: C | AL25: C | AM25: P
B49: Legenda
B50: R | C50: Responsável | D50: Somente um responsável pela entrega
B51: Rv | C51: Revisão | D51: Responsável pela revisão
B52: A | C52: Aprovação | D52: Responsável pela aprovação
B53: C | C53: Consultado | D53: Pessoa a ser consultada antes que a decisão seja tomada
B54: I | C54: Informado | D54: Pessoa a ser informada sobre a decisão tomada
B55: P | C55: Participante | D55: Pessoa que suporta ou participa da execução

Sheet Orçamento 1
C2: Orçamento
B3: ='Declaração de Escopo do Projeto'!B7:H7 -> Vertex Londrina 360
B5: Recursos | C5: Custo Unitário (U$) | D5: Quantidade | E5: Total (R$)
B6: Folha A4 de cimento geopolimérico branca | C6: 180000 | D6: 35 | E6: =C6*D6 -> 6300000
B7: Folha A4 de cimento geopolimérico colorida | C7: 200000 | D7: 1 | E7: =C7*D7 -> 200000
B8: Rolo de fita crepe 28 mm × 50 m | C8: 2500000 | D8: 1 | E8: =C8*D8 -> 2500000
B9: Tubo de cola | C9: 3000000 | D9: 1 | E9: =C9*D9 -> 3000000
B10: Kit de barbante 3 metros | C10: 1500000 | D10: 1 | E10: =C10*D10 -> 1500000
B11: Kit com 20 canudos plásticos | C11: 800000 | D11: 1 | E11: =C11*D11 -> 800000
B12: Kit com 20 palitos grandes | C12: 1500000 | D12: 2 | E12: =C12*D12 -> 3000000
B13: Tesoura grande | C13: 1100000 | D13: 1 | E13: =C13*D13 -> 1100000
B18: Custo do Projeto (A) | E18: =SUM(E6:E17) -> 18400000
B19: Reserva de Contingência (B) | E19: 1600000
B20: Custo Final (A + B) | E20: =E18+E19 -> 20000000

Sheet Orçamento 2
C2: Orçamento
B3: ='Declaração de Escopo do Projeto'!B7:H7 -> Vertex Londrina 360
B5: Recursos | C5: Custo Unitário (U$) | D5: Quantidade | E5: Total (R$)
B6: Folha A4 de cimento geopolimérico branca | C6: 180000 | D6: 35 | E6: =C6*D6 -> 6300000
B7: Folha A4 de cimento geopolimérico colorida | C7: 200000 | D7: 1 | E7: =C7*D7 -> 200000
B8: Rolo de fita crepe 28 mm × 50 m | C8: 2500000 | D8: 1 | E8: =C8*D8 -> 2500000
B9: Tubo de cola | C9: 3000000 | D9: 1 | E9: =C9*D9 -> 3000000
B10: Kit de barbante 3 metros | C10: 1500000 | D10: 1 | E10: =C10*D10 -> 1500000
B11: Kit com 20 canudos plásticos | C11: 800000 | D11: 2 | E11: =C11*D11 -> 1600000
B12: Kit com 20 palitos grandes | C12: 1500000 | D12: 1 | E12: =C12*D12 -> 1500000
B13: Tesoura grande | C13: 1100000 | D13: 1 | E13: =C13*D13 -> 1100000
B18: Custo do Projeto (A) | E18: =SUM(E6:E17) -> 17700000
B19: Reserva de Contingência (B) | E19: 1600000
B20: Custo Final (A + B) | E20: =E18+E19 -> 19300000
B24: Motivação para alteração do Plano de Aquisição O orçamento sofreu alteração devido ao fim do estoque do material "Kit com 20 palitos grandes", reduzindo sua aquisição de 2 para 1 e sendo necessário incluir um "Kit com 20 canudos plásticos" no novo plano de aquisições. Não houve aplicação de multa, pois a alteração foi devido ao estoque disponível no mercado.

Sheet Qualidade
F2: Qualidade
D3: Londrina 360
C5: PONTO A VERIFICAR | I5: STATUS
A6: DOCUMENTAÇÃO | B6: 1 | C6: O projeto fez uso de um macro planning? | I6: SIM
B7: 2 | C7: O cumprimento do cronograma foi realizado? | I7: SIM
B8: 3 | C8: A EAP contemplou as fases de planejamento e execução? | I8: SIM
B9: 4 | C9: Os gastos até a data presente do cronograma atendem ao orçamento previsto? | I9: SIM
B10: 5 | C10: Os cargos e funções foram escritos e seguidos? | I10: SIM
B11: 6 | C11: Os custos das obras sofreram alteração ao longo da execução? | I11: SIM
B12: 7 | C12: O escopo sofreu alteração ao logo da execução do projeto? | I12: SIM
B13: 8 | C13: As estapas e escopo foram aprovadas pelo sponsor? | I13: SIM
A14: EXECUÇÃO | B14: 9 | C14: As estapas do projeto foram obecedidas e cumpridas como planejado? | I14: SIM
B15: 10 | C15: Houve disperdício de material? Ou falta dele? | I15: NÃO
B16: 11 | C16: Os materiais usados na construção eram compatíveis com o que foi descrito e solicitado? | I16: SIM
B17: 12 | C17: A construção atendeu as normas ambientais? Atendeu os requisitos de sustentabilidade? | I17: SIM
B18: 13 | C18: Os riscos foram conhecidos e descritos? | I18: SIM
B19: 14 | C19: A construção utilizou materiais não oficiais? | I19: NÃO
B20: 15 | C20: O fornecedor atendeu aos requisitos de qualidade dos materiais? | I20: SIM
B21: 16 | C21: A construção foi realizada dentro da área prevista de 1m²? | I21: SIM
A24: Procedimentos de Controle de Qualidade
A25: O controle de qualidade do projeto será realizado na conclusão de cada entrega antes que a mesma seja enviada ao cliente final. O controle de qualidade será realizado através de inspeção nas entregas utilizando-se os checklists apresentados em anexo e respectivamente, os seus indicadores, a fim de manter a qualidade do projeto e alimentar o processo de melhoria contínua. Foram editadas Boas Práticas (Anexo II) para assegurar uniformidade no processo.
A26: Processos de Monitoramento
A27: Requisito | B27: Indicador | C27: Meta | D27: Técnica de Aferição | E27: Frequência | F27: Quem Mede | G27: Onde Registra | H27: Plano de Resposta
H28: Ação | I28: Quando | J28: Responsável
A29: Materiais | B29: Aferição de conformidade | C29: Obter 100% de material de qualidade para construir a torre (folhas de nicraly, cola adesiva plástica, fita adesiva, ferramenta de corte) | D29: Visual e táctil | E29: 1 | F29: Comprador | G29: Termo de aceite de produto entregue* | H29: Testar o material | I29: Ao receber | J29: Carlos Eduardo
A30: Sustentabilidade | B30: Conformidade dos materiais e descarte | C30: 100% dos materiais aprovados e resíduos segregados | D30: Inspeção visual e conferência da lista de materiais | E30: Em cada aquisição e ao final da montagem | F30: Carlos Eduardo | G30: Checklist de sustentabilidade | H30: Segregar resíduos e substituir item não conforme | I30: Na identificação do desvio | J30: Carlos Eduardo
A31: Uniformidade no processo | B31: Aderência ao croqui e ao método de montagem | C31: 100% das etapas críticas executadas conforme o padrão aprovado | D31: Checklist por etapa, inspeção visual e registro fotográfico | E31: Ao concluir cada etapa de montagem | F31: Carlos Eduardo | G31: Checklist de execução e registro fotográfico | H31: Corrigir a etapa antes de iniciar a seguinte | I31: Imediatamente após a inspeção | J31: Carlos Eduardo
A32: Solidez na construção | B32: Estabilidade, prumo e integridade da torre | C32: Torre autoportante, sem tombamento, deformação crítica ou apoio externo | D32: Inspeção visual, verificação de prumo e teste progressivo de estabilidade | E32: Durante a montagem e antes da entrega | F32: Carlos Eduardo | G32: Termo de inspeção estrutural | H32: Reforçar emendas e contraventamentos e repetir o teste | I32: Antes da apresentação final | J32: Carlos Eduardo

Sheet Plano de Riscos
K2: Plano de Resposta aos Riscos
B3: ='Declaração de Escopo do Projeto'!B7:H7 -> Vertex Londrina 360
B6: Identificação do Risco | K6: Resposta ao Risco
G7: Análise Qualitativa | M7: Análise Quantitativa
B8: ID | C8: Descrição do Risco | D8: Causa | E8: Modo de detecção | F8: Consequências | G8: Probabilidade | H8: Impacto previsto | I8: Classificação do Risco | J8: Resposta ao Risco | K8: Estratégia para Ação | L8: Responsável | M8: Custo | N8: Prazo | O8: Situação
B9: 1 | C9: Queda de estrutura | D9: Falha estrutural | E9: Visual | F9: Reprovação do projeto | G9: Média | H9: Alto | I9: Alto | J9: Mitigar | K9: Revisar croquis proposto/ conceber projeto autoportante | L9: XXXXXXX | M9: 20000000 | N9: Durante e após a produção | O9: Ação realizada
B10: D | C10: Descrição do Risco | D10: Causa | E10: Modo de detecção | F10: Consequências | G10: Probabilidade | H10: Impacto previsto | I10: Classificação do Risco | J10: Resposta ao Risco | K10: Estratégia para Ação | L10: Responsável | M10: Custo | N10: Prazo | O10: Situação
B11: R01 | C11: Colapso ou tombamento estrutural da torre durante a montagem, os testes ou a apresentação. | D11: Ação do vento; contraventamento insuficiente; falha nas emendas; distribuição inadequada de cargas; sobrecarga estrutural. | E11: Inspeção visual de prumo e emendas; medição de deslocamentos; teste progressivo de estabilidade; identificação de deformações, fissuras ou oscilações excessivas. | F11: Danos à estrutura; necessidade de reconstrução; atraso; risco às pessoas; reprovação sumária da entrega perante a banca. | G11: Média | H11: Muito alto, podendo resultar em perda integral da entrega. | I11: Crítico | J11: Mitigar | K11: Validar previamente o projeto estrutural; instalar contraventamentos; reforçar pontos de emenda; controlar cargas; executar protótipo e teste de estabilidade antes da apresentação. | L11: Design e Engenharia | M11: A estimar | N11: Antes da montagem definitiva e da apresentação | O11: Aberto
B12: R02 | C12: Interrupção do fornecimento ou aumento de preços do cimento geopolimérico em razão da dependência do fornecedor exclusivo Bueno. | D12: Existência de fornecedor único; fornecimento apenas por kits fechados; ausência de estoque de segurança ou alternativa previamente aprovada. | E12: Acompanhamento de estoque; confirmação formal do pedido; monitoramento dos prazos de fabricação e entrega; comunicação periódica com o fornecedor. | F12: Paralisação da montagem da fachada; atraso no cronograma; aumento de custos; impossibilidade de reposição tempestiva de materiais. | G12: Alta | H12: Alto, com potencial de interromper uma etapa crítica do projeto. | I12: Crítico | J12: Mitigar | K12: Antecipar a compra; reservar os kits necessários; negociar garantia de fornecimento e prazo; manter estoque de segurança; avaliar previamente materiais substitutos permitidos pelo regulamento. | L12: Suprimentos e Logística | M12: A estimar | N12: Imediato e antes do início da montagem da fachada | O12: Aberto
B13: R03 | C13: Autuação e aplicação de multa por infração às regras concorrenciais. | D13: Realização de transação monetária, compra compartilhada, rateio ou transferência de materiais com empresas concorrentes. | E13: Revisão prévia das aquisições e pagamentos; conferência de comprovantes; validação dos fornecedores e participantes de cada transação; auditoria dos registros financeiros. | F13: Multa de US$ 1.000.000,00; comprometimento do orçamento; possível desclassificação; danos reputacionais e questionamentos de conformidade. | G13: Baixa | H13: US$ 1.000.000,00, além dos possíveis efeitos administrativos e reputacionais. | I13: Crítico | J13: Evitar | K13: Proibir compras, pagamentos ou compartilhamento de custos com concorrentes; centralizar aquisições em responsável autorizado; documentar todas as transações; submeter situações duvidosas à validação prévia. | L13: Gerente do Projeto / Auditor | M13: Custo preventivo a estimar; exposição máxima de US$ 1.000.000,00 | N13: Durante todo o projeto, especialmente antes das aquisições | O13: Aberto
B14: R04 | C14: Estouro do orçamento em decorrência de alterações solicitadas após a apresentação formal do plano. | D14: Definição incompleta do escopo; requisitos não validados; falhas de planejamento; aprovação antecipada de uma solução ainda sujeita a alterações. | E14: Registro e comparação das solicitações de mudança; acompanhamento da linha de base do escopo e dos custos; revisão periódica do orçamento. | F14: Acréscimo obrigatório de US$ 100.000,00 por alteração; consumo das reservas; inviabilidade financeira; redução de recursos para outras entregas. | G14: Média | H14: US$ 100.000,00 por solicitação de mudança realizada após a apresentação formal. | I14: Alto | J14: Evitar | K14: Congelar o escopo antes da apresentação; validar requisitos e desenho com todas as áreas; realizar revisão técnica final; exigir análise de impacto e aprovação do Sponsor para qualquer mudança posterior. | L14: Gerente do Projeto / Sponsor | M14: Custo preventivo a estimar; exposição de US$ 100.000,00 por alteração | N14: Antes da apresentação formal do plano | O14: Aberto
B15: R05 | C15: Divergência entre a geometria da torre construída e o croqui técnico homologado. | D15: Erros de medição; interpretação inadequada do desenho; perda de escala; cortes imprecisos; falhas de montagem ou ausência de gabaritos. | E15: Comparação periódica entre a obra e o croqui; medição de altura, largura, alinhamento e diagonais; uso de gabaritos; inspeção fotográfica das etapas. | F15: Perda de pontos nos critérios de simetria e estética; retrabalho; consumo adicional de material; possível rejeição parcial da entrega. | G15: Média | H15: Alto, com efeito direto na avaliação técnica e estética. | I15: Alto | J15: Mitigar | K15: Converter o croqui em desenho cotado; definir tolerâncias; utilizar gabaritos; conferir medidas por etapa; homologar um protótipo antes da montagem final. | L15: Design e Engenharia | M15: A estimar | N15: Durante toda a montagem, com validação final antes da entrega | O15: Aberto
B16: R06 | C16: Perda, rasgo ou inutilização das placas cimentícias em formato A4 durante o manuseio e a montagem. | D16: Dobragem ou colagem inadequada; manuseio incorreto; armazenamento impróprio; umidade; cortes errados; ausência de peças avulsas para reposição. | E16: Inspeção no recebimento; controle individual das placas; acompanhamento das perdas durante corte, dobra e colagem; verificação do estoque remanescente. | F16: Impossibilidade de fechar 100% da fachada; falhas estéticas; retrabalho; atraso; impossibilidade de devolução ou recompra de kits fracionados. | G16: Alta | H16: Alto, podendo impedir a conclusão integral da fachada. | I16: Crítico | J16: Mitigar | K16: Treinar a equipe; testar previamente a técnica de dobra e colagem; armazenar as placas em local seco e protegido; manusear uma peça por vez; planejar cortes; adquirir margem de segurança por meio de kits adicionais completos, se permitido. | L16: Design e Engenharia / Suprimentos e Logística | M16: A estimar | N16: Antes e durante a montagem da fachada | O16: Aberto
B17: R07 | C17: Extrapolação do horário-limite de entrega da obra física ou do dossiê documental. | D17: Atrasos na montagem; retrabalho; falhas na integração das equipes; documentação incompleta; ausência de controle do caminho crítico; submissão deixada para o último momento. | E17: Monitoramento do cronograma; verificação de marcos intermediários; checklist da entrega; contagem regressiva; acompanhamento separado da obra física e do dossiê. | F17: Pontuação mínima no critério prazo; perda de pontos; entrega incompleta; possível desclassificação do projeto. | G17: Média | H17: Muito alto, podendo comprometer integralmente a avaliação do projeto. | I17: Crítico | J17: Mitigar | K17: Estabelecer prazo interno anterior às 16h30; concluir a montagem e o dossiê com antecedência; designar responsáveis distintos pela obra e pela documentação; realizar simulação de entrega; manter contingência para impressão e submissão. | L17: Gerente do Projeto / Documentação | M17: A estimar | N17: Entrega obrigatória até 16h30, com prazo interno antecipado | O17: Aberto
B30: Preparado por: Matheus e Marciane | M30: Número do Doc:
B31: Aprovado por: | M31: Data:
C35: Matriz de graduação do risco | E35: Impacto | J35: Respostas ao risco
E36: Baixo | F36: Médio | G36: Alto | J36: Mitigar
C37: Probabilidade | D37: Alta | E37: Médio | F37: Alto | G37: Alto | J37: Aceitar
D38: Média | E38: Baixo | F38: Médio | G38: Alto | J38: Transferir
D39: Baixa | E39: Baixo | F39: Baixo | G39: Médio | J39: Eliminar
C41: Probabilidade = Chance de ocorrência do risco
C42: Impacto = Efeitos, consequência sobre os objetivos do projeto, se o evento de risco ocorrer

Sheet Stakeholders
B3: ='Declaração de Escopo do Projeto'!B7:H7 -> Vertex Londrina 360
B5: Identificação | C5: Descrição | D5: Poder | E5: Interesse | F5: Gerenciamento | G5: Legenda
B6: Nick O' Neil | C6: Sponsor/ Cliente | D6: 3 | E6: 1 | F6: Gerenciar de perto | G6: Poder
B7: Bueno | C7: Fornedor | D7: 3 | E7: 1 | F7: Gerenciar de perto | G7: 3 | H7: Alto
B8: Ricardo | C8: Professor | D8: 3 | E8: 1 | F8: Gerenciar de perto | G8: 2 | H8: Médio
B9: Mercado Terra X e Lumina | C9: Concorrente | D9: 1 | E9: 0 | F9: Acompanhar | G9: 1 | H9: Baixo
G10: Interesse
G11: 1 | H11: Positivo
G12: 2 | H12: Negativo
G13: 0 | H13: Neutro

Sheet Lições Aprendidas
A2: Lições Aprendidas
A3: Fase | B3: Ocorrência | C3: Informações Complementares
A4: Apresentação e Aprovação do Escopo Estratégico | B4: Não foi realizado um estudo mais aprofundado sobre o histórico dos Stakeholders | C4: Consultar o linkedin para identificar o histórico do Stakeholders
B5: Não foi indicado na Missão da Vertex Engenharia Brasil qual é o prazo estimado para o alcance da Missão | C5: Definido que a missão será alcançada em 2030
A6: Iniciação | B6: Destaque a consulta ao especialista no início do projeto, assim informações importantes para o bom andamento do projeto já foram obtidas na iniciação
A7: Aprovação do Croquis Estrutural | B7: Nesta etapa foi discutido que poderia ter alguma restrição referente aos materiais disponíveis para a construção da Torre. Ponto importantíssimo. Alguns recursos tem limite de quantidade.
A8: Plano de Aquisições | B8: Após a aprovação do Croquis, time demorou para elaborar o plano de aquisições, mesmo sabendo das restrições de materias, ficando como últimos a adquirir os materiais | C8: Melhorar a organização para estruturar o plano, visto a concorrência entre os projetos.
A13: O que nós já fazemos?
A14: O que fazemos e precisamos parar de fazer?
A15: O que não fazemos e precisamos começar a fazer?
A16: O que fazemos e precisamos melhorar a fazer? DMAIX? PDCA?
C18: Seguradora

Sheet Plano de Comunicação
F2: Plano de Comunicação
C3: Vertex Londrina 360
C5: Os projetos deverão ter o plano de comunicação descrito, com todas as reuniões e eventos definidos conforme abrangência e natureza dos projetos.
A8: 2. COMUNICAÇÃO
A9: Fase | B9: Conteúdo (o quê?) | C9: Público-alvo (para quem?) | D9: Canal (como?) | E9: Periodicidade ou momento (quando?) | F9: Responsável (quem?)
A10: Durante o Planejamento do Projeto (reuniões de definições) | B10: Briefing e alinhamento dos requisitos | C10: Equipe do projeto | D10: Reunião presencial | E10: Início do projeto | F10: Gerente de Projeto
B11: Apresentação e aprovação do escopo estratégico | C11: Sponsor / Cliente | D11: Reunião presencial | E11: 0.4375 | F11: Gerente de Projeto
B12: Apresentação do sumário de entregas e lista de materiais | C12: Sponsor / Equipe | D12: Reunião presencial | E12: 0.45833333 | F12: Gerente de Projeto
B13: Apresentação e aprovação do croqui estrutural | C13: Sponsor / Cliente | D13: Reunião presencial | E13: 0.47916667 | F13: Responsável Técnico
B14: Apresentação e aprovação do plano de aquisições | C14: Sponsor / Cliente | D14: Reunião presencial | E14: 0.5 | F14: Responsável de Suprimentos
A17: Durante a Execução e Controle do Projeto | B17: Liberação do terreno e delimitação da área de implantação | C17: Equipe do projeto | D17: Reunião presencial | E17: 0.58333333 | F17: Sponsor
B18: Alinhamento para início da construção | C18: Equipe de execução | D18: Reunião presencial | E18: Antes do início da montagem | F18: Gerente de Projeto
B19: Comunicação do andamento, riscos e desvios | C19: Gerente do Projeto / Equipe | D19: Comunicação direta / reunião | E19: Durante a construção | F19: Responsável Técnico
B20: Comunicação da conclusão da torre e entrega da documentação | C20: Sponsor / Cliente | D20: Reunião presencial | E20: 0.6875 | F20: Gerente de Projeto
A22: Após entrega do projeto | B22: Apresentação dos resultados e lições aprendidas | C22: Sponsor / Equipe / Cliente | D22: Plenária presencial | E22: 16:30 às 17:30 | F22: Gerente de Projeto
B23: Comunicação de encerramento do projeto | C23: Sponsor / Cliente / Equipe | D23: Reunião presencial | E23: 17:30 às 18:00 | F23: Gerente de Projeto
C34: Seguradora

Sheet Solicitação de Mudanças
E2: Solicitação de mudanças Nº: 1
B3: ='Declaração de Escopo do Projeto'!B7:H7 -> Vertex Londrina 360
B5: Este documento somente deve ser preenchido em caso de mudanças no projeto (escopo, prazo, custo, etc).
B7: Esta seção deve ser preenchida pelo requisitante.
B9: Nome do Requisitante: João — Suprimentos e Logística | H9: Data Submetida: 23/10/2026
B10: Nome do Projeto: Vertex Londrina 360 | H10: Prioridade: Alta
B12: Descrição da Solicitação
B14: Revisar o plano de aquisições devido à indisponibilidade de estoque do Kit com 20 palitos grandes. Reduzir a quantidade de 2 para 1 kit e aumentar o Kit com 20 canudos plásticos de 1 para 2 kits, mantendo os demais materiais e requisitos aprovados.
B24: Motivo da Solicitação
B26: O fornecedor Bueno não dispunha da quantidade originalmente prevista de palitos. A substituição parcial por canudos permitiu preservar a solução estrutural, evitar interrupção da montagem e manter o projeto dentro das regras de aquisição e do limite orçamentário.
B33: Impactos | C33: Escopo: sem alteração do objetivo, da escala 1:350, da área de 1 m², da tripla vocação ou dos critérios de aceitação. Alteração restrita à composição da lista de materiais.
C34: Custo: custo do projeto reduzido de R$ 18.400.000,00 para R$ 17.700.000,00. Custo final, com contingência de R$ 1.600.000,00, reduzido de R$ 20.000.000,00 para R$ 19.300.000,00.
C35: Prazo: sem alteração da entrega final às 16h30. A aquisição revisada foi concluída às 14h40.
C36: Outros / Comentários: não houve aplicação de multa. A rastreabilidade da substituição deve ser mantida no orçamento, plano de aquisições, qualidade e controle de versões.
B38: Documentos de Referência
B39: • Orçamento 1 — linha de base aprovada.
B40: • Orçamento 2 — orçamento revisado e justificativa da alteração.
B41: • Cronograma Inicial — marco de materiais adquiridos às 14h40.
B42: • Declaração de Escopo do Projeto — objetivo, entregas, premissas e exclusões.
B43: • Plano de Riscos — risco de indisponibilidade do fornecedor e resposta de mitigação.
B44: • Qualidade — conformidade dos materiais e inspeção no recebimento.
B45: • Matriz de Responsabilidades — atribuições de Suprimentos, Auditoria e Gerência do Projeto.
B46: Anexos
B47: • Lista de materiais originalmente aprovada.
B48: • Cotação/posição de estoque do fornecedor Bueno.
B49: • Comparativo entre Orçamento 1 e Orçamento 2.
... B69: Aprovações
B71: Patrocinador ou Gestor: Nick O´Neil — Aprovado | H71: Data: 23/10/2026
B72: Gerente do Projeto: Fernanda — Aprovado | H72: Data: 23/10/2026

Sheet Termo de Encerramento
F2: Termo de encerramento do Projeto
B3: ='Declaração de Escopo do Projeto'!B7:H7 -> Vertex Londrina 360
B5: 1. Nome do Projeto
B7: Vertex Londrina 360 | K7: Cliente
B9: Data: | D9: 23/10/2026 | E9: Responsável GP: | G9: Fernanda | J9: x | K9: Corporativo
E11: Responsável Cliente: | G11: Warren Buffet
B13: Classificação do processo: | E13: CORPORATIVO
B15: 2. Entregas do Projeto
B17: Nº | C17: Descrição | I17: Responsável
B18: 1 | C18: Pacote gerencial consolidado: TAP, escopo, EAP, cronograma, orçamento, planos e matriz RACI. | I18: Fernanda / Matheus / Marciane
B19: 2 | C19: Croqui homologado e torre física autoportante em escala 1:350, dentro da área de 1 m². | I19: Everton / Fabi
B20: 3 | C20: Aquisição e disponibilização dos materiais conforme plano revisado e limite orçamentário. | I20: João / Bueno
B21: 4 | C21: Inspeções de qualidade, auditoria, dossiê final, lições aprendidas e termo de encerramento. | I21: Carlos Eduardo / Fernanda
B24: 3. Status do Projeto / Avaliação
B26: [X] Encerrado | G26: [ ] Excelente
B27: [ ] Cancelado | G27: [X] Muito Bom
B28: [ ] Suspenso | G28: [ ] Bom
B29: [ ] Paralisado | G29: [ ] Regular
G30: [ ] Insuficiente
B32: 4. Justificativa para o Status
B33: O projeto Vertex Londrina 360 foi encerrado após a execução das entregas gerenciais e físicas previstas, conforme os registros disponíveis no workbook.
B34: Os marcos contemplaram aprovação do escopo, entregas, materiais, croqui, aquisições, liberação da área, conclusão da torre e encerramento em 23/10/2026. O custo final revisado foi de R$ 19.300.000,00, incluindo R$ 1.600.000,00 de contingência, ficando R$ 700.000,00 abaixo do teto de R$ 20.000.000,00. A alteração de materiais decorreu da indisponibilidade do kit de palitos: reduziu-se um kit e acrescentou-se um kit de canudos, sem multa e sem alteração do escopo. Os controles documentais registram cumprimento do cronograma, aderência à EAP, funções definidas, gastos dentro do orçamento e aprovação do escopo pelo cliente.
B38: A avaliação final é Muito Bom, considerando o atendimento dos objetivos, a economia obtida e as oportunidades de melhoria identificadas em stakeholders e aquisições.
B39: 5. Conclusões e Lições Aprendidas
B40: Conclusão: o projeto demonstrou integração entre gestão, engenharia, suprimentos, documentação, qualidade, riscos e sustentabilidade na entrega do protótipo.
B41: • Partes interessadas: aprofundar a análise prévia dos stakeholders e registrar histórico, influência, expectativas e critérios de aceite desde a iniciação. • Iniciação: manter a consulta antecipada a especialistas, pois ela permitiu identificar restrições relevantes antes da execução. • Aquisições: iniciar o plano logo após a aprovação do croqui e reservar materiais críticos, reduzindo exposição à concorrência e à falta de estoque. • Materiais: confirmar disponibilidade e alternativas permitidas antes da compra, com rastreabilidade das mudanças e impactos no orçamento. • Qualidade e riscos: preservar inspeções por etapa, registro fotográfico, teste de estabilidade e acompanhamento dos riscos estruturais e de fornecimento.
B46: Recomendação: arquivar os checklists finais, formalizar o aceite do cliente e encerrar administrativamente os riscos residuais após a aprovação deste termo.
B47: 7. Responsáveis pela Autorização de Encerramento do Projeto
B49: Nome | F49: Chave | G49: Contato
B50: Fernanda (Gerente de Projeto) | F50: fernanda.alves@example.com | G50: (61) 99101-2201
B51: Nick O´Neil | F51: nick@example.com | G51: (97) 8101-2360
B52: Carlos Eduardo (Auditor/Gerente de qualidade) | F52: carlos.eduardo@example.com | G52: (61) 99103-2203
B54: 8. Data / Responsável pela Aprovação:
B56: Data: | D56: 23/10/2026 | E56: Responsável pela aprovação: | G56: Nick O'Neil

Sheet Controle de Versões
E2: Controle de Versões
B3: ='Declaração de Escopo do Projeto'!B7:H7 -> Vertex Londrina 360
B5: # | C5: Data | D5: Documento | E5: Versão Anterior | F5: Versão Atual | G5: Responsável | H5: Descrição do conteúdo do documento e principais mudanças em relação a versão anterior
B6: 1 | C6: 46318 | D6: Termo de abertura do projeto | E6: 0 | F6: 1 | G6: Matheus | H6: Criação
B7: 2 | C7: 46318 | D7: Termo de abertura do projeto | E7: 1 | F7: 2 | G7: Marciane | H7: Alteração do orçamento estimado com base no plano de aquisições.
